Workbook
Name _GoBack: 'AVAILABILITY DASHBOARD'!#REF!
Name AA: 'CONTAINER HANDLERS FAULTS'!$FDV$1

Sheet RELIABILITY SNAP SHOT
D2: UPTIME % | F2: TOTAL CALLS | G2: AV. CALL/EQUIP. | H2: MTBF | J2: MTTR | L2: UTILIZATION
B3: =CONCATENATE("DATE:"," ",'OTHER REPORTS'!A3) -> DATE: TUESDAY 21ST OCTOBER 2025 | D3: TARGET | E3: ACTUAL | H3: TARGET | I3: ACTUAL | J3: TARGET | K3: ACTUAL | L3: TARGET | M3: ACTUAL
B4: SHIP TO SHORE GANTRY | C4: STS | D4: 90 | E4: ='AVAILABILITY DASHBOARD'!P6 -> 90.690104 | F4: =SUM('AVAILABILITY DASHBOARD'!M6:M12) -> 13 | G4: =F4/7 -> 1.8571429 | I4: ='AVAILABILITY DASHBOARD'!Q6 -> 0.57897377 | J4: 0.03125 | K4: ='AVAILABILITY DASHBOARD'!R6 -> 0.11226852
B5: RAIL MOUNTED GANTRY | C5: RMG | D5: 95 | E5: ='AVAILABILITY DASHBOARD'!P23 -> 86.892361 | F5: =SUM('AVAILABILITY DASHBOARD'!#REF!) -> #REF! | G5: =F5/2 -> #REF! | I5: ='AVAILABILITY DASHBOARD'!Q23 -> 0.89513889 | J5: 0.03125 | K5: ='AVAILABILITY DASHBOARD'!R23 -> 0.048611111
B6: RUBBER TYRE GANTRY | C6: RTG | D6: 87 | E6: ='AVAILABILITY DASHBOARD'!P32 -> 75.89367 | F6: =SUM('AVAILABILITY DASHBOARD'!M32:M63) -> 8 | G6: =F6/34 -> 0.23529412 | I6: ='AVAILABILITY DASHBOARD'!Q32 -> 0.82602294 | J6: 0.03125 | K6: ='AVAILABILITY DASHBOARD'!R32 -> 2.0726981
B7: STS SPREADERS | C7: STSSPD | D7: 92 | E7: ='AVAILABILITY DASHBOARD'!H266 -> 93.548387
B8: MANUAL SPREADERS | C8: MSPD | D8: 92 | E8: ='AVAILABILITY DASHBOARD'!H270 -> 100
B9: OVER HEIGHT SPREADERS | C9: OHS | D9: 92 | E9: ='AVAILABILITY DASHBOARD'!H271 -> 92.857143
B10: REACHSTACKERS | C10: R/S | D10: 80 | E10: ='AVAILABILITY DASHBOARD'!#REF! -> #REF! | F10: =SUM('AVAILABILITY DASHBOARD'!M99:M117) -> 3 | G10: =F10/20 -> 0.15 | I10: ='AVAILABILITY DASHBOARD'!#REF! -> #REF! | J10: 0.03125 | K10: ='AVAILABILITY DASHBOARD'!#REF! -> #REF!
B11: EMPTY CONTAINER HANDLERS | C11: ECH | D11: 85 | E11: ='AVAILABILITY DASHBOARD'!#REF! -> #REF! | F11: =SUM('AVAILABILITY DASHBOARD'!M119:M120) -> 0 | G11: =F11/5 -> 0 | I11: ='AVAILABILITY DASHBOARD'!#REF! -> #REF! | J11: 0.03125 | K11: ='AVAILABILITY DASHBOARD'!#REF! -> #REF!
B12: GANTRY SPREADERS | C12: GSPD | D12: 90 | E12: ='AVAILABILITY DASHBOARD'!H268 -> 94.339623
B13: REEFER POINTS | C13: RP | D13: 95 | E13: ='AVAILABILITY DASHBOARD'!#REF! -> #REF!
B14: TERMINAL TRACTORS | C14: TT | D14: 80 | E14: ='AVAILABILITY DASHBOARD'!#REF! -> #REF!
B15: SKELETAL TRAILER | C15: ST | D15: 80 | E15: ='AVAILABILITY DASHBOARD'!#REF! -> #REF!
B16: LOWBED TRAILER | C16: LBT | D16: 80 | E16: ='AVAILABILITY DASHBOARD'!#REF! -> #REF!

Sheet EXECUTIVE SUMMARY1
A1: CONTAINER TERMINAL ENGINEERING EQUIPMENT AVALABILITY SUMMARY:
A2: DATE | B2: ='OTHER REPORTS'!A3 -> TUESDAY 21ST OCTOBER 2025
A3: EQUIPMENT GROUP | B3: HOLDING | C3: AVAILABLE AS @ 0700 | D3: BROKENDOWN | E3: LAST 24HRS % AVAILABILITY | G3: SET TARGET | H3: ON PLANNED MAINTENANCE (TODAY)
A4: S.T.S | B4: ='AVAILABILITY DASHBOARD'!D5 -> 16 | C4: ='AVAILABILITY DASHBOARD'!E5 -> 15 | D4: =B4-C4 -> 1 | E4: ='AVAILABILITY DASHBOARD'!P6 -> 90.690104 | F4: ='AVAILABILITY DASHBOARD'!E8 -> 14.510417 | G4: 0.9 | H4: ='OTHER REPORTS'!D32 -> NIL
A5: R.M.G | B5: ='AVAILABILITY DASHBOARD'!D22 -> 8 | C5: ='AVAILABILITY DASHBOARD'!E22 -> 7 | D5: =B5-C5 -> 1 | E5: ='AVAILABILITY DASHBOARD'!P23 -> 86.892361 | F5: ='AVAILABILITY DASHBOARD'!E25 -> 6.9513889 | G5: 0.95 | H5: ='OTHER REPORTS'!#REF! -> #REF!
A6: R.T.G | B6: ='AVAILABILITY DASHBOARD'!D31 -> 52 | C6: ='AVAILABILITY DASHBOARD'!E31 -> 43 | D6: =B6-C6 -> 9 | E6: ='AVAILABILITY DASHBOARD'!P32 -> 75.89367 | F6: ='AVAILABILITY DASHBOARD'!E31 -> 43 | G6: 0.9 | H6: ='OTHER REPORTS'!#REF! -> #REF!
A7: M.H.C | B7: 2 | C7: ='AVAILABILITY DASHBOARD'!E93 -> 2 | D7: =B7-C7 -> 0 | E7: ='AVAILABILITY DASHBOARD'!P94 -> 74.479167 | F7: ='AVAILABILITY DASHBOARD'!E94 -> 2.9791667 | G7: 0.9 | H7: ='OTHER REPORTS'!#REF! -> #REF!
A8: R/STACKERS | B8: ='AVAILABILITY DASHBOARD'!D98 -> 19 | C8: ='AVAILABILITY DASHBOARD'!E98 -> 10 | D8: =B8-C8 -> 9 | E8: ='AVAILABILITY DASHBOARD'!#REF! -> #REF! | F8: ='AVAILABILITY DASHBOARD'!#REF! -> #REF! | G8: 0.9 | H8: ='OTHER REPORTS'!D36 -> NIL
A9: E.C.H | B9: ='AVAILABILITY DASHBOARD'!D118 -> 21 | C9: ='AVAILABILITY DASHBOARD'!E118 -> 13 | D9: =B9-C9 -> 8 | E9: ='AVAILABILITY DASHBOARD'!#REF! -> #REF! | F9: ='AVAILABILITY DASHBOARD'!#REF! -> #REF! | G9: 0.9 | H9: ='OTHER REPORTS'!#REF! -> #REF!
A10: T/TRACTOR | B10: ='AVAILABILITY DASHBOARD'!D140 -> 116 | C10: ='AVAILABILITY DASHBOARD'!E140 -> 85 | D10: =B10-C10 -> 31 | E10: ='AVAILABILITY DASHBOARD'!#REF! -> #REF! | F10: ='AVAILABILITY DASHBOARD'!#REF! -> #REF! | G10: 0.9 | H10: ='OTHER REPORTS'!D37 -> KTT193, TTT167
A11: S/TRAILERS | B11: ='AVAILABILITY DASHBOARD'!#REF! -> #REF! | C11: ='AVAILABILITY DASHBOARD'!#REF! -> #REF! | D11: =B11-C11 -> #REF! | E11: ='AVAILABILITY DASHBOARD'!#REF! -> #REF! | F11: ='AVAILABILITY DASHBOARD'!#REF! -> #REF! | G11: 0.9 | H11: ='OTHER REPORTS'!D38 -> NIL
A13: SHIP TO SHORE STATUS REPORT
A14: EQUIP. | B14: OPERATION STATUS REMARKS
A15: STS 1602 | B15: =CONCATENATE('OTHER REPORTS'!D42," (",'OTHER REPORTS'!C42," )") -> (O.K (AVAILABLE) )
A16: STS 1702 | B16: =CONCATENATE('OTHER REPORTS'!D43," (",'OTHER REPORTS'!C43," )") -> (O.K (AVAILABLE) )
A17: STS 1703 | B17: =CONCATENATE('OTHER REPORTS'!D44," (",'OTHER REPORTS'!C44," )") -> (O.K (AVAILABLE) )
A18: STS 1803 | B18: =CONCATENATE('OTHER REPORTS'!D45," (",'OTHER REPORTS'!C45," )") -> (O.K (AVAILABLE) )
A19: STS 1804 | B19: =CONCATENATE('OTHER REPORTS'!D46," (",'OTHER REPORTS'!C46," )") -> (O.K (AVAILABLE) )
A20: STS 1901 | B20: =CONCATENATE('OTHER REPORTS'!D47," (",'OTHER REPORTS'!C47," )") -> (O.K (AVAILABLE) )
A21: STS 1902 | B21: =CONCATENATE('OTHER REPORTS'!D48," (",'OTHER REPORTS'!C48," )") -> (O.K (AVAILABLE) )
A22: STS 1903 | B22: =CONCATENATE('OTHER REPORTS'!D49," (",'OTHER REPORTS'!C49," )") -> (O.K (AVAILABLE) )
A23: STS 1904 | B23: =CONCATENATE('OTHER REPORTS'!D50," (",'OTHER REPORTS'!C50," )") -> (O.K (AVAILABLE) )
A24: STS 1905 | B24: =CONCATENATE('OTHER REPORTS'!D51," (",'OTHER REPORTS'!C51," )") -> (O.K (AVAILABLE) )
A25: STS 2101 | B25: =CONCATENATE('OTHER REPORTS'!D52," (",'OTHER REPORTS'!C52," )") -> (NOT (AVAILABLE) )
A26: STS 2102 | B26: =CONCATENATE('OTHER REPORTS'!D53," (",'OTHER REPORTS'!C53," )") -> (O.K (AVAILABLE) )

Sheet EXECUTIVE SUMMARY
A1: CONTAINER TERMINAL ENGINEERING EQUIPMENT AVAILABILITY SUMMARY
A2: DATE | B2: ='OTHER REPORTS'!A3 -> TUESDAY 21ST OCTOBER 2025
A3: EQUIPMENT GROUP | B3: HOLDING | C3: AVAILABILE AS @0700HRS | D3: BREAKDOWN | E3: LAST 24HRS % AVAILABILITY | G3: SET TARGET | H3: DOWN TIME (MIN) | I3: EQUIPMENT ON PREVENTIVE MAINTENANCE - TODAY
A4: STS | B4: ='AVAILABILITY DASHBOARD'!D5 -> 16 | C4: ='AVAILABILITY DASHBOARD'!E5 -> 15 | D4: =B4-C4 -> 1 | E4: ='AVAILABILITY DASHBOARD'!P6 -> 90.690104 | F4: =C4 -> 15 | G4: 0.9 | H4: ='AVAILABILITY DASHBOARD'!G22 -> 89.375 | I4: EQPT CLASS | J4: EQPT NO. 1 | K4: EQPT NO. 2
A5: RMG | B5: ='AVAILABILITY DASHBOARD'!D22 -> 8 | C5: ='AVAILABILITY DASHBOARD'!E22 -> 7 | D5: =B5-C5 -> 1 | E5: ='AVAILABILITY DASHBOARD'!P23 -> 86.892361 | F5: =C5 -> 7 | G5: 0.9 | H5: ='AVAILABILITY DASHBOARD'!G31 -> 62.916667 | I5: STS | J5: =CONCATENATE('OTHER REPORTS'!C32) -> STS1804 | K5: =CONCATENATE('OTHER REPORTS'!D32) -> NIL
A6: RTG | B6: ='AVAILABILITY DASHBOARD'!D31 -> 52 | C6: ='AVAILABILITY DASHBOARD'!E31 -> 43 | D6: =B6-C6 -> 9 | E6: ='AVAILABILITY DASHBOARD'!P32 -> 75.89367 | F6: =C6 -> 43 | G6: 0.9 | H6: ='AVAILABILITY DASHBOARD'!G93 -> 942.29167 | I6: RMG | J6: =CONCATENATE('OTHER REPORTS'!C33) -> NIL | K6: =CONCATENATE('OTHER REPORTS'!D33) -> NIL
A7: MHC | B7: ='AVAILABILITY DASHBOARD'!D93 -> 4 | C7: ='AVAILABILITY DASHBOARD'!E93 -> 2 | D7: =B7-C7 -> 2 | E7: ='AVAILABILITY DASHBOARD'!P94 -> 74.479167 | F7: =C7 -> 2 | G7: 0.9 | H7: ='AVAILABILITY DASHBOARD'!G98 -> 61.25 | I7: RTG | J7: =CONCATENATE('OTHER REPORTS'!C34) -> RTG211 | K7: =CONCATENATE('OTHER REPORTS'!D34) -> RTG217
A8: R/STACKERS | B8: 19 | C8: ='AVAILABILITY DASHBOARD'!E98 -> 10 | D8: =B8-C8 -> 9 | E8: ='AVAILABILITY DASHBOARD'!P119 -> 66.45172 | F8: =C8 -> 10 | G8: 0.9 | H8: ='AVAILABILITY DASHBOARD'!G118 -> 578.95833 | I8: MHC | J8: =CONCATENATE('OTHER REPORTS'!C35) -> NIL | K8: =CONCATENATE('OTHER REPORTS'!D35) -> NIL
A9: ECH | B9: 21 | C9: ='AVAILABILITY DASHBOARD'!E118 -> 13 | D9: =B9-C9 -> 8 | E9: ='AVAILABILITY DASHBOARD'!P99 -> 49.214181 | F9: =C9 -> 13 | G9: 0.9 | H9: ='AVAILABILITY DASHBOARD'!G140 -> 422.70833 | I9: R/STACKERS-ECH | J9: =CONCATENATE('OTHER REPORTS'!C36) -> HK39 | K9: =CONCATENATE('OTHER REPORTS'!D36) -> NIL
A10: T/TRACTORS | B10: 116 | C10: ='AVAILABILITY DASHBOARD'!E140 -> 85 | D10: =B10-C10 -> 31 | E10: ='AVAILABILITY DASHBOARD'!P141 -> 73.515326 | F10: =C10 -> 85 | G10: 0.9 | H10: ='AVAILABILITY DASHBOARD'!G262 -> 1843.3333 | I10: T/TRACTORS | J10: =CONCATENATE('OTHER REPORTS'!C37) -> KTT221 | K10: =CONCATENATE('OTHER REPORTS'!D37) -> KTT193, TTT167
A11: S/TRAILERS | B11: ='AVAILABILITY DASHBOARD'!D263 -> 158 | C11: ='AVAILABILITY DASHBOARD'!E263 -> 131 | D11: =B11-C11 -> 27 | E11: ='AVAILABILITY DASHBOARD'!L263 -> 82.911392 | F11: =C11 -> 131 | G11: 0.9 | I11: TRAILERS | J11: =CONCATENATE('OTHER REPORTS'!C38) -> HTR263 | K11: =CONCATENATE('OTHER REPORTS'!D38) -> NIL
I12: SPREADERS | J12: =CONCATENATE('OTHER REPORTS'!C39) -> OHS179 | K12: =CONCATENATE('OTHER REPORTS'!D39) -> NIL
I13: MAN LIFT | J13: =CONCATENATE('OTHER REPORTS'!C40) -> NIL | K13: =CONCATENATE('OTHER REPORTS'!D40) -> NIL
I14: PRTs | J14: =CONCATENATE('OTHER REPORTS'!C41) -> NIL | K14: =CONCATENATE('OTHER REPORTS'!D41) -> NIL
A16: SHIP TO SHORE STATUS REPORT
A17: EQUIPMENT | B17: OPERATIONA STATUS REMARKS
A18: STS1603 | B18: ='OTHER REPORTS'!C42 -> O.K (AVAILABLE)
A19: STS1604 | B19: ='OTHER REPORTS'!C43 -> O.K (AVAILABLE)
A20: STS1605 | B20: ='OTHER REPORTS'!C44 -> O.K (AVAILABLE)
A21: STS1606 | B21: ='OTHER REPORTS'!C45 -> O.K (AVAILABLE)
A22: STS1804 | B22: ='OTHER REPORTS'!C46 -> O.K (AVAILABLE)
A23: STS1901 | B23: ='OTHER REPORTS'!C47 -> O.K (AVAILABLE)
A24: STS1902 | B24: ='OTHER REPORTS'!C48 -> O.K (AVAILABLE)
A25: STS1903 | B25: ='OTHER REPORTS'!C49 -> O.K (AVAILABLE)
A26: STS1904 | B26: ='OTHER REPORTS'!C50 -> O.K (AVAILABLE)
A27: STS1905 | B27: ='OTHER REPORTS'!C51 -> O.K (AVAILABLE)
A28: STS2101 | B28: ='OTHER REPORTS'!C52 -> NOT (AVAILABLE)
A29: STS2102 | B29: ='OTHER REPORTS'!C53 -> O.K (AVAILABLE)
A30: STS2103 | B30: ='OTHER REPORTS'!C54 -> O.K (AVAILABLE)

Sheet AVAILABILITY SNAP SHOT 
B1: GANTRY EQUIPMENT | J1: MOBILE PLANT EQUIPMENT
B2: =G4 -> 92.797599 | E2: UPTIME % | H2: =G4 -> 92.797599 | J2: =P4 -> 74.418524 | M2: UPTIME % | O2: =P4 -> 74.418524
B3: =G4 -> 92.797599 | C3: =CONCATENATE("DATE:"," ",'OTHER REPORTS'!A3) -> DATE: TUESDAY 21ST OCTOBER 2025 | E3: TARGET | F3: ACTUAL | J3: =P4 -> 74.418524 | K3: =CONCATENATE("DATE:"," ",'OTHER REPORTS'!A3) -> DATE: TUESDAY 21ST OCTOBER 2025 | M3: TARGET | N3: ACTUAL
C4: SHIP TO SHORE GANTRY | D4: STS | E4: 90 | F4: ='AVAILABILITY DASHBOARD'!P6 -> 90.690104 | G4: =(F4+F5+F6+F7+F8)/500*100 -> 92.797599 | K4: REACHSTACKERS | L4: R/S | M4: 90 | N4: ='AVAILABILITY DASHBOARD'!P99 -> 49.214181 | P4: =(N4+N5+N6+N7+N8)/500*100 -> 74.418524
C5: RAIL MOUNTED GANTRY | D5: RMG | E5: 90 | F5: ='AVAILABILITY DASHBOARD'!P23 -> 86.892361 | K5: EMPTY CONTAINER HANDLERS | L5: ECH | M5: 90 | N5: ='AVAILABILITY DASHBOARD'!P119 -> 66.45172
C6: STS SPREADERS | D6: STSSPD | E6: 90 | F6: ='AVAILABILITY DASHBOARD'!H266 -> 93.548387 | K6: TERMINAL TRACTORS | L6: TT | M6: 90 | N6: ='AVAILABILITY DASHBOARD'!P141 -> 73.515326
C7: MANUAL SPREADERS | D7: MSPD | E7: 90 | F7: ='AVAILABILITY DASHBOARD'!H270 -> 100 | K7: SKELETAL TRAILERS | L7: ST | M7: 90 | N7: ='AVAILABILITY DASHBOARD'!L263 -> 82.911392
C8: OVER HEIGHT SPREADERS | D8: OHS | E8: 90 | F8: ='AVAILABILITY DASHBOARD'!H271 -> 92.857143 | K8: LOWBED TRAILERS | L8: LBT | M8: 90 | N8: ='AVAILABILITY DASHBOARD'!L264 -> 100
B11: =G4 -> 92.797599 | J11: =P4 -> 74.418524
B13: YARD GANTRY EQUIPMENT
B14: =G16 -> 86.178115 | E14: UPTIME % | H14: =G16 -> 86.178115
B15: =G16 -> 86.178115 | C15: =CONCATENATE("DATE:"," ",'OTHER REPORTS'!A3) -> DATE: TUESDAY 21ST OCTOBER 2025 | E15: TARGET | F15: ACTUAL
C16: RUBBER TYRE GANTRY | D16: RTG | E16: 90 | F16: ='AVAILABILITY DASHBOARD'!P32 -> 75.89367 | G16: =(F16+F17+F18+F19)/400*100 -> 86.178115
C17: MOBILE HARBOUR CRANES | D17: MHC | E17: 90 | F17: ='AVAILABILITY DASHBOARD'!P94 -> 74.479167
C18: RTG SPREADERS | D18: RTG.SPD | E18: 90 | F18: ='AVAILABILITY DASHBOARD'!H268 -> 94.339623
C19: MHC SPREADERS | D19: MHC.SPD | E19: 90 | F19: ='AVAILABILITY DASHBOARD'!H269 -> 100
B22: =G16 -> 86.178115

Sheet AVAILABILITY DASHBOARD
A1: KPA/ES-CTE/FM/007 | D1: ='OTHER REPORTS'!B3 -> EQUIPMENT AVAILABILITY AS AT 0700HRS | S1: ='OTHER REPORTS'!A3 -> TUESDAY 21ST OCTOBER 2025
A2: EQUIPMENT | D2: HOLDING | E2: AVAILABLE | F2: REQUIRE. | G2: DOWNTIME (MIN) | H2: DOWNTIME | L2: (%) UPTIME | M2: NO. OF CALLS | N2: MTBF | O2: MTTR | P2: AVERAGE PERFORMANCE/ TARGET | S2: FAULT NOTIFICATIONS PER EQUIPMENT
P3: AVILB. | Q3: MTBF | R3: MTTR
P4: AVAIL | Q4: MTBF | R4: MTTR
A5: STS | D5: 16 | E5: ='STS RMG FAULTS'!L6+'STS RMG FAULTS'!L7 -> 15 | F5: 15 | H5: SHIP TO SHORE GANTRIES
G6: =CONVERT(H6,"hr","min") -> 0 | H6: ='STS RMG FAULTS'!O9 -> 0 | I6: =H6 -> 0 | J6: =I6/0.00069444444444444 -> 0 | K6: =(1-I6)/0.00069444444444444 -> 1440 | L6: =((1440-(J6))/1440)*100 -> 100 | M6: ='STS RMG FAULTS'!P9 -> 10 | N6: =((1440-J6)/(M6+1))*0.00069444444444444 -> 0.090909091 | O6: =((1440-K6)/(M6))*0.00069444444444444 -> -6.3159354e-16 | P6: =AVERAGE(L6:L21) -> 90.690104 | Q6: =AVERAGEIF(N6:N21,">0",N10:N21) -> 0.57897377 | R6: =AVERAGEIF(O6:O21,">0",O6:O21) -> 0.11226852 | S6: =CONCATENATE("STS1603: ",'STS RMG FAULTS'!B9,"_",'STS RMG FAULTS'!G9,"_",'STS RMG FAULTS'!K9) -> STS1603: HOIST_NIL_NIL
G7: =CONVERT(H7,"hr","min") -> 0 | H7: ='STS RMG FAULTS'!O10 -> 0 | I7: =H7 -> 0 | J7: =I7/0.00069444444444444 -> 0 | K7: =(1-I7)/0.00069444444444444 -> 1440 | L7: =((1440-(J7))/1440)*100 -> 100 | M7: ='STS RMG FAULTS'!P10 -> 0 | N7: =((1440-J7)/(M7+1))*0.00069444444444444 -> 1 | O7: =((1440-K7)/(M7))*0.00069444444444444 -> #DIV/0! | P7: 90 | Q7: 0.9 | R7: 0.03125 | S7: =CONCATENATE("STS1604: ",'STS RMG FAULTS'!B10,"_",'STS RMG FAULTS'!G10,"_",'STS RMG FAULTS'!K10) -> STS1604: NIL_NIL_NIL
A8: TERM. 1 | B8: ='STS RMG FAULTS'!L6 -> 10 | D8: AVE. | E8: =AA8 -> 14.510417 | G8: =CONVERT(H8,"hr","min") -> 0 | H8: ='STS RMG FAULTS'!O11 -> 0 | I8: =H8 -> 0 | J8: =I8/0.00069444444444444 -> 0 | K8: =(1-I8)/0.00069444444444444 -> 1440 | L8: =((1440-(J8))/1440)*100 -> 100 | M8: ='STS RMG FAULTS'!P11 -> 0 | N8: =((1440-J8)/(M8+1))*0.00069444444444444 -> 1 | O8: =((1440-K8)/(M8))*0.00069444444444444 -> #DIV/0! | S8: =CONCATENATE("STS1605: ",'STS RMG FAULTS'!B11,"_",'STS RMG FAULTS'!G11,"_",'STS RMG FAULTS'!K11) -> STS1605: NIL_NIL_NIL | AA8: =P6/100*16 -> 14.510417
C9: =AVERAGE(L6:L15) -> 93.125 | G9: =CONVERT(H9,"hr","min") -> 0 | H9: ='STS RMG FAULTS'!O12 -> 0 | I9: =H9 -> 0 | J9: =I9/0.00069444444444444 -> 0 | K9: =(1-I9)/0.00069444444444444 -> 1440 | L9: =((1440-(J9))/1440)*100 -> 100 | M9: ='STS RMG FAULTS'!P12 -> 0 | N9: =((1440-J9)/(M9+1))*0.00069444444444444 -> 1 | O9: =((1440-K9)/(M9))*0.00069444444444444 -> #DIV/0! | S9: =CONCATENATE("STS1606: ",'STS RMG FAULTS'!B12,"_",'STS RMG FAULTS'!G12,"_",'STS RMG FAULTS'!K12) -> STS1606: NIL_NIL_NIL
G10: =CONVERT(H10,"hr","min") -> 2.2916667 | H10: ='STS RMG FAULTS'!O13 -> 0.038194444 | I10: =H10 -> 0.038194444 | J10: =I10/0.00069444444444444 -> 55 | K10: =(1-I10)/0.00069444444444444 -> 1385 | L10: =((1440-(J10))/1440)*100 -> 96.180556 | M10: ='STS RMG FAULTS'!P13 -> 3 | N10: =((1440-J10)/(M10+1))*0.00069444444444444 -> 0.24045139 | O10: =((1440-K10)/(M10))*0.00069444444444444 -> 0.012731481 | S10: =CONCATENATE("STS1804: ",'STS RMG FAULTS'!B13,"_",'STS RMG FAULTS'!G13,"_",'STS RMG FAULTS'!K13) -> STS1804: TRAVELLING_TRAVELLING_40FT CONFIRMATION
A11: TERM.2 | B11: ='STS RMG FAULTS'!L7 -> 5 | G11: =CONVERT(H11,"hr","min") -> 0 | H11: ='STS RMG FAULTS'!O14 -> 0 | I11: =H11 -> 0 | J11: =I11/0.00069444444444444 -> 0 | K11: =(1-I11)/0.00069444444444444 -> 1440 | L11: =((1440-(J11))/1440)*100 -> 100 | M11: ='STS RMG FAULTS'!P14 -> 0 | N11: =((1440-J11)/(M11+1))*0.00069444444444444 -> 1 | O11: =((1440-K11)/(M11))*0.00069444444444444 -> #DIV/0! | S11: =CONCATENATE("STS1901: ",'STS RMG FAULTS'!B14,"_",'STS RMG FAULTS'!G14,"_",'STS RMG FAULTS'!K14) -> STS1901: NIL_NIL_NIL
C12: =AVERAGE(L16:L21) -> 86.631944 | G12: =CONVERT(H12,"hr","min") -> 0 | H12: ='STS RMG FAULTS'!O15 -> 0 | I12: =H12 -> 0 | J12: =I12/0.00069444444444444 -> 0 | K12: =(1-I12)/0.00069444444444444 -> 1440 | L12: =((1440-(J12))/1440)*100 -> 100 | M12: ='STS RMG FAULTS'!P15 -> 0 | N12: =((1440-J12)/(M12+1))*0.00069444444444444 -> 1 | O12: =((1440-K12)/(M12))*0.00069444444444444 -> #DIV/0! | S12: =CONCATENATE("STS1902: ",'STS RMG FAULTS'!B15,"_",'STS RMG FAULTS'!G15,"_",'STS RMG FAULTS'!K15) -> STS1902: NIL_NIL_NIL
G13: =CONVERT(H13,"hr","min") -> 11.458333 | H13: ='STS RMG FAULTS'!O16 -> 0.19097222 | I13: =H13 -> 0.19097222 | J13: =I13/0.00069444444444444 -> 275 | K13: =(1-I13)/0.00069444444444444 -> 1165 | L13: =((1440-(J13))/1440)*100 -> 80.902778 | M13: ='STS RMG FAULTS'!P16 -> 5 | N13: =((1440-J13)/(M13+1))*0.00069444444444444 -> 0.13483796 | O13: =((1440-K13)/(M13))*0.00069444444444444 -> 0.038194444 | S13: =CONCATENATE("STS1903: ",'STS RMG FAULTS'!B16,"_",'STS RMG FAULTS'!G16,"_",'STS RMG FAULTS'!K16) -> STS1903: HOISTING/UMBILICAL SPRING/SLING SNAPPED_UMBLICAL CABLE SPRING SNAPPED_TRAVELLING
G14: =CONVERT(H14,"hr","min") -> 2.7083333 | H14: ='STS RMG FAULTS'!O17 -> 0.045138889 | I14: =H14 -> 0.045138889 | J14: =I14/0.00069444444444444 -> 65 | K14: =(1-I14)/0.00069444444444444 -> 1375 | L14: =((1440-(J14))/1440)*100 -> 95.486111 | M14: ='STS RMG FAULTS'!P17 -> 3 | N14: =((1440-J14)/(M14+1))*0.00069444444444444 -> 0.23871528 | O14: =((1440-K14)/(M14))*0.00069444444444444 -> 0.015046296 | S14: =CONCATENATE("STS1904: ",'STS RMG FAULTS'!B17,"_",'STS RMG FAULTS'!G17,"_",'STS RMG FAULTS'!K17) -> STS1904: SPD COMMUNICATION_NIL_TWIN UP FAULT
G15: =CONVERT(H15,"hr","min") -> 24.791667 | H15: ='STS RMG FAULTS'!O18 -> 0.41319444 | I15: =H15 -> 0.41319444 | J15: =I15/0.00069444444444444 -> 595 | K15: =(1-I15)/0.00069444444444444 -> 845 | L15: =((1440-(J15))/1440)*100 -> 58.680556 | M15: ='STS RMG FAULTS'!P18 -> 2 | N15: =((1440-J15)/(M15+1))*0.00069444444444444 -> 0.19560185 | O15: =((1440-K15)/(M15))*0.00069444444444444 -> 0.20659722 | S15: =CONCATENATE("STS1905: ",'STS RMG FAULTS'!B18,"_",'STS RMG FAULTS'!G18,"_",'STS RMG FAULTS'!K18) -> STS1905: HOIST WIRE ROPE SNAPPED_READY AT 1610HRS/LOWERING_CABLE REEL REEL SPRING SHACKLE SNAPPED
G16: =CONVERT(H16,"hr","min") -> 28.958333 | H16: ='STS RMG FAULTS'!O19 -> 0.48263889 | I16: =H16 -> 0.48263889 | J16: =I16/0.00069444444444444 -> 695 | K16: =(1-I16)/0.00069444444444444 -> 745 | L16: =((1440-(J16))/1440)*100 -> 51.736111 | M16: ='STS RMG FAULTS'!P19 -> 2 | N16: =((1440-J16)/(M16+1))*0.00069444444444444 -> 0.1724537 | O16: =((1440-K16)/(M16))*0.00069444444444444 -> 0.24131944 | S16: =CONCATENATE("STS2101: ",'STS RMG FAULTS'!B19,"_",'STS RMG FAULTS'!G19,"_",'STS RMG FAULTS'!K19) -> STS2101: NIL_LOCK SENSOR OFFSET/CARTENARY WIRE PULLEY DETACHED.OUT AT 1940HRS_OUT
G17: =CONVERT(H17,"hr","min") -> 0 | H17: ='STS RMG FAULTS'!O20 -> 0 | I17: =H17 -> 0 | J17: =I17/0.00069444444444444 -> 0 | K17: =(1-I17)/0.00069444444444444 -> 1440 | L17: =((1440-(J17))/1440)*100 -> 100 | M17: ='STS RMG FAULTS'!P20 -> 0 | N17: =((1440-J17)/(M17+1))*0.00069444444444444 -> 1 | O17: =((1440-K17)/(M17))*0.00069444444444444 -> #DIV/0! | S17: =CONCATENATE("STS2102: ",'STS RMG FAULTS'!B20,"_",'STS RMG FAULTS'!G20,"_",'STS RMG FAULTS'!K20) -> STS2102: NIL_NIL_NIL
G18: =CONVERT(H18,"hr","min") -> 19.166667 | H18: ='STS RMG FAULTS'!O21 -> 0.31944444 | I18: =H18 -> 0.31944444 | J18: =I18/0.00069444444444444 -> 460 | K18: =(1-I18)/0.00069444444444444 -> 980 | L18: =((1440-(J18))/1440)*100 -> 68.055556 | M18: ='STS RMG FAULTS'!P21 -> 2 | N18: =((1440-J18)/(M18+1))*0.00069444444444444 -> 0.22685185 | O18: =((1440-K18)/(M18))*0.00069444444444444 -> 0.15972222 | S18: =CONCATENATE("STS2103: ",'STS RMG FAULTS'!B21,"_",'STS RMG FAULTS'!G21,"_",'STS RMG FAULTS'!K21) -> STS2103: OP. CABIN DOOR REPAIR- AT 1105HRS_READY AT 1915HRS_LOCK SIGNAL
G19: =CONVERT(H19,"hr","min") -> 0 | H19: ='STS RMG FAULTS'!O22 -> 0 | I19: =H19 -> 0 | J19: =I19/0.00069444444444444 -> 0 | K19: =(1-I19)/0.00069444444444444 -> 1440 | L19: =((1440-(J19))/1440)*100 -> 100 | M19: ='STS RMG FAULTS'!P22 -> 0 | N19: =((1440-J19)/(M19+1))*0.00069444444444444 -> 1 | O19: =((1440-K19)/(M19))*0.00069444444444444 -> #DIV/0! | S19: =CONCATENATE("STS2201: ",'STS RMG FAULTS'!B22,"_",'STS RMG FAULTS'!G22,"_",'STS RMG FAULTS'!K22) -> STS2201: NIL_NIL_NIL
G20: =CONVERT(H20,"hr","min") -> 0 | H20: ='STS RMG FAULTS'!O23 -> 0 | I20: =H20 -> 0 | J20: =I20/0.00069444444444444 -> 0 | K20: =(1-I20)/0.00069444444444444 -> 1440 | L20: =((1440-(J20))/1440)*100 -> 100 | M20: ='STS RMG FAULTS'!P23 -> 0 | N20: =((1440-J20)/(M20+1))*0.00069444444444444 -> 1 | O20: =((1440-K20)/(M20))*0.00069444444444444 -> #DIV/0! | S20: =CONCATENATE("STS2202: ",'STS RMG FAULTS'!B23,"_",'STS RMG FAULTS'!G23,"_",'STS RMG FAULTS'!K23) -> STS2202: NIL_NIL_NIL
G21: =CONVERT(H21,"hr","min") -> 0 | H21: ='STS RMG FAULTS'!O24 -> 0 | I21: =H21 -> 0 | J21: =I21/0.00069444444444444 -> 0 | K21: =(1-I21)/0.00069444444444444 -> 1440 | L21: =((1440-(J21))/1440)*100 -> 100 | M21: ='STS RMG FAULTS'!P24 -> 0 | N21: =((1440-J21)/(M21+1))*0.00069444444444444 -> 1 | O21: =((1440-K21)/(M21))*0.00069444444444444 -> #DIV/0! | S21: =CONCATENATE("STS2203: ",'STS RMG FAULTS'!B24,"_",'STS RMG FAULTS'!G24,"_",'STS RMG FAULTS'!K24) -> STS2203: NIL_NIL_NIL
A22: RMG | D22: 8 | E22: ='STS RMG FAULTS'!L27+'STS RMG FAULTS'!L28 -> 7 | F22: 8 | G22: =SUM(G6:G21) -> 89.375 | H22: RAIL MOUNTED GANTRIES
G23: =CONVERT(H23,"hr","min") -> 60 | H23: ='STS RMG FAULTS'!O29 -> 1 | I23: =H23 -> 1 | J23: =I23/0.00069444444444444 -> 1440 | K23: =(1-I23)/0.00069444444444444 -> 0 | L23: =((1440-(J23))/1440)*100 -> -6.3159354e-13 | M23: ='STS RMG FAULTS'!P29 -> 0 | N23: =((1440-J23)/(M23+1))*0.00069444444444444 -> -6.3159354e-15 | O23: =((1440-K23)/(M23))*0.00069444444444444 -> #DIV/0! | P23: =AVERAGE(L23:L30) -> 86.892361 | Q23: =AVERAGEIF(N23:N28,">0",N23:N28) -> 0.89513889 | R23: =AVERAGEIF(O23:O28,">0",O23:O28) -> 0.048611111 | S23: =CONCATENATE("RMG05: ",'STS RMG FAULTS'!B29,"_",'STS RMG FAULTS'!G29,"_",'STS RMG FAULTS'!K29) -> RMG05: CONTROL ON -OUT_OUT_OUT | AA23: =P23/100*8 -> 6.9513889
G24: =CONVERT(H24,"hr","min") -> 2.9166667 | H24: ='STS RMG FAULTS'!O30 -> 0.048611111 | I24: =H24 -> 0.048611111 | J24: =I24/0.00069444444444444 -> 70 | K24: =(1-I24)/0.00069444444444444 -> 1370 | L24: =((1440-(J24))/1440)*100 -> 95.138889 | M24: ='STS RMG FAULTS'!P30 -> 1 | N24: =((1440-J24)/(M24+1))*0.00069444444444444 -> 0.47569444 | O24: =((1440-K24)/(M24))*0.00069444444444444 -> 0.048611111 | P24: 90 | Q24: 0.95 | R24: 0.03125 | S24: =CONCATENATE("RMG06: ",'STS RMG FAULTS'!B30,"_",'STS RMG FAULTS'!G30,"_",'STS RMG FAULTS'!K30) -> RMG06: NIL_NIL_SLOW MOTION
A25: TERM. 1 | B25: ='STS RMG FAULTS'!L27 -> 5 | D25: AVE | E25: =AA23 -> 6.9513889 | G25: =CONVERT(H25,"hr","min") -> 0 | H25: ='STS RMG FAULTS'!O31 -> 0 | I25: =H25 -> 0 | J25: =I25/0.00069444444444444 -> 0 | K25: =(1-I25)/0.00069444444444444 -> 1440 | L25: =((1440-(J25))/1440)*100 -> 100 | M25: ='STS RMG FAULTS'!P31 -> 0 | N25: =((1440-J25)/(M25+1))*0.00069444444444444 -> 1 | O25: =((1440-K25)/(M25))*0.00069444444444444 -> #DIV/0! | S25: =CONCATENATE("RMG07: ",'STS RMG FAULTS'!B31,"_",'STS RMG FAULTS'!G31,"_",'STS RMG FAULTS'!K31) -> RMG07: NIL_NIL_NIL
C26: =AVERAGE(L23:L28) -> 82.523148 | G26: =CONVERT(H26,"hr","min") -> 0 | H26: ='STS RMG FAULTS'!O32 -> 0 | I26: =H26 -> 0 | J26: =I26/0.00069444444444444 -> 0 | K26: =(1-I26)/0.00069444444444444 -> 1440 | L26: =((1440-(J26))/1440)*100 -> 100 | M26: ='STS RMG FAULTS'!P32 -> 0 | N26: =((1440-J26)/(M26+1))*0.00069444444444444 -> 1 | O26: =((1440-K26)/(M26))*0.00069444444444444 -> #DIV/0! | S26: =CONCATENATE("RMG08: ",'STS RMG FAULTS'!B32,"_",'STS RMG FAULTS'!G32,"_",'STS RMG FAULTS'!K32) -> RMG08: NIL_NIL_NIL
G27: =CONVERT(H27,"hr","min") -> 0 | H27: ='STS RMG FAULTS'!O33 -> 0 | I27: =H27 -> 0 | J27: =I27/0.00069444444444444 -> 0 | K27: =(1-I27)/0.00069444444444444 -> 1440 | L27: =((1440-(J27))/1440)*100 -> 100 | M27: ='STS RMG FAULTS'!P33 -> 0 | N27: =((1440-J27)/(M27+1))*0.00069444444444444 -> 1 | O27: =((1440-K27)/(M27))*0.00069444444444444 -> #DIV/0! | S27: =CONCATENATE("RMG09: ",'STS RMG FAULTS'!B33,"_",'STS RMG FAULTS'!G33,"_",'STS RMG FAULTS'!K33) -> RMG09: NIL_NIL_NIL
A28: TERM.2 | B28: ='STS RMG FAULTS'!L28 -> 2 | G28: =CONVERT(H28,"hr","min") -> 0 | H28: ='STS RMG FAULTS'!O34 -> 0 | I28: =H28 -> 0 | J28: =I28/0.00069444444444444 -> 0 | K28: =(1-I28)/0.00069444444444444 -> 1440 | L28: =((1440-(J28))/1440)*100 -> 100 | M28: ='STS RMG FAULTS'!P34 -> 0 | N28: =((1440-J28)/(M28+1))*0.00069444444444444 -> 1 | O28: =((1440-K28)/(M28))*0.00069444444444444 -> #DIV/0! | S28: =CONCATENATE("RMG10: ",'STS RMG FAULTS'!B34,"_",'STS RMG FAULTS'!G34,"_",'STS RMG FAULTS'!K34) -> RMG10: NIL_NIL_NIL
C29: =AVERAGE(L29:L30) -> 100 | G29: =CONVERT(H29,"hr","min") -> 0 | H29: ='STS RMG FAULTS'!O35 -> 0 | I29: =H29 -> 0 | J29: =I29/0.00069444444444444 -> 0 | K29: =(1-I29)/0.00069444444444444 -> 1440 | L29: =((1440-(J29))/1440)*100 -> 100 | M29: ='STS RMG FAULTS'!P35 -> 0 | N29: =((1440-J29)/(M29+1))*0.00069444444444444 -> 1 | O29: =((1440-K29)/(M29))*0.00069444444444444 -> #DIV/0! | S29: =CONCATENATE("RMG2-11: ",'STS RMG FAULTS'!B35,"_",'STS RMG FAULTS'!G35,"_",'STS RMG FAULTS'!K35) -> RMG2-11: NIL_NIL_NIL
G30: =CONVERT(H30,"hr","min") -> 0 | H30: ='STS RMG FAULTS'!O36 -> 0 | I30: =H30 -> 0 | J30: =I30/0.00069444444444444 -> 0 | K30: =(1-I30)/0.00069444444444444 -> 1440 | L30: =((1440-(J30))/1440)*100 -> 100 | M30: ='STS RMG FAULTS'!P36 -> 0 | N30: =((1440-J30)/(M30+1))*0.00069444444444444 -> 1 | O30: =((1440-K30)/(M30))*0.00069444444444444 -> #DIV/0! | S30: =CONCATENATE("RMG2-12: ",'STS RMG FAULTS'!B36,"_",'STS RMG FAULTS'!G36,"_",'STS RMG FAULTS'!K36) -> RMG2-12: NIL_NIL_NIL
A31: RTG | D31: 52 | E31: ='RTG&HARBOUR FAULTS'!K6+'RTG&HARBOUR FAULTS'!K7 -> 43 | F31: 40 | G31: =SUM(G23:G30) -> 62.916667 | H31: RUBBER TYRED GANTRIES
G32: =CONVERT(H32,"hr","min") -> 0 | H32: ='RTG&HARBOUR FAULTS'!N10 -> 0 | I32: =H32 -> 0 | J32: =I32/0.00069444444444444 -> 0 | K32: =(1-I32)/0.00069444444444444 -> 1440 | L32: =((1440-(J32))/1440)*100 -> 100 | M32: ='RTG&HARBOUR FAULTS'!O10 -> 0 | N32: =((1440-J32)/(M32+1))*0.00069444444444444 -> 1 | O32: =((1440-K32)/(M32))*0.00069444444444444 -> #DIV/0! | P32: =AVERAGE(L32:L92) -> 75.89367 | Q32: =AVERAGEIF(N32:N79,">0",N32:N79) -> 0.82602294 | R32: =AVERAGEIF(O32:O79,">0",O32:O79) -> 2.0726981 | S32: =CONCATENATE("RTG12: ",'RTG&HARBOUR FAULTS'!B10,"_",'RTG&HARBOUR FAULTS'!F10,"_",'RTG&HARBOUR FAULTS'!J10) -> RTG12: NIL_NIL_NIL
G33: =CONVERT(H33,"hr","min") -> 0 | H33: ='RTG&HARBOUR FAULTS'!N11 -> 0 | I33: =H33 -> 0 | J33: =I33/0.00069444444444444 -> 0 | K33: =(1-I33)/0.00069444444444444 -> 1440 | L33: =((1440-(J33))/1440)*100 -> 100 | M33: ='RTG&HARBOUR FAULTS'!O11 -> 0 | N33: =((1440-J33)/(M33+1))*0.00069444444444444 -> 1 | O33: =((1440-K33)/(M33))*0.00069444444444444 -> #DIV/0! | P33: 90 | Q33: 0.86944444 | R33: 0.03125 | S33: =CONCATENATE("RTG13: ",'RTG&HARBOUR FAULTS'!B11,"_",'RTG&HARBOUR FAULTS'!F11,"_",'RTG&HARBOUR FAULTS'!J11) -> RTG13: NIL_NIL_NIL
A34: TERM. 1 | B34: ='RTG&HARBOUR FAULTS'!K6 -> 22 | D34: AVE. | E34: =AA35 -> 39.464709 | G34: =CONVERT(H34,"hr","min") -> 0 | H34: ='RTG&HARBOUR FAULTS'!N12 -> 0 | I34: =H34 -> 0 | J34: =I34/0.00069444444444444 -> 0 | K34: =(1-I34)/0.00069444444444444 -> 1440 | L34: =((1440-(J34))/1440)*100 -> 100 | M34: ='RTG&HARBOUR FAULTS'!O12 -> 0 | N34: =((1440-J34)/(M34+1))*0.00069444444444444 -> 1 | O34: =((1440-K34)/(M34))*0.00069444444444444 -> #DIV/0! | S34: =CONCATENATE("RTG14: ",'RTG&HARBOUR FAULTS'!B12,"_",'RTG&HARBOUR FAULTS'!F12,"_",'RTG&HARBOUR FAULTS'!J12) -> RTG14: NIL_NIL_NIL
C35: =AVERAGE(L32,L33,L34,L35,L36,L37,L38,L39,L40,L41,L42,L43,L44,L45,L46,L47,L48,L49,L50,L51,L52,L53,L54,L55,L56,L57,L58,L59,L60,L61,L62,L63) -> 67.263455 | G35: =CONVERT(H35,"hr","min") -> 0 | H35: ='RTG&HARBOUR FAULTS'!N13 -> 0 | I35: =H35 -> 0 | J35: =I35/0.00069444444444444 -> 0 | K35: =(1-I35)/0.00069444444444444 -> 1440 | L35: =((1440-(J35))/1440)*100 -> 100 | M35: ='RTG&HARBOUR FAULTS'!O13 -> 0 | N35: =((1440-J35)/(M35+1))*0.00069444444444444 -> 1 | O35: =((1440-K35)/(M35))*0.00069444444444444 -> #DIV/0! | S35: =CONCATENATE("RTG15: ",'RTG&HARBOUR FAULTS'!B13,"_",'RTG&HARBOUR FAULTS'!F13,"_",'RTG&HARBOUR FAULTS'!J13) -> RTG15: NIL_NIL_NIL | AA35: =P32/100*52 -> 39.464709
G36: =CONVERT(H36,"hr","min") -> 0 | H36: ='RTG&HARBOUR FAULTS'!N14 -> 0 | I36: =H36 -> 0 | J36: =I36/0.00069444444444444 -> 0 | K36: =(1-I36)/0.00069444444444444 -> 1440 | L36: =((1440-(J36))/1440)*100 -> 100 | M36: ='RTG&HARBOUR FAULTS'!O14 -> 0 | N36: =((1440-J36)/(M36+1))*0.00069444444444444 -> 1 | O36: =((1440-K36)/(M36))*0.00069444444444444 -> #DIV/0! | S36: =CONCATENATE("RTG16: ",'RTG&HARBOUR FAULTS'!B14,"_",'RTG&HARBOUR FAULTS'!F14,"_",'RTG&HARBOUR FAULTS'!J14) -> RTG16: NIL_NIL_NIL
A37: TERM. 2 | B37: ='RTG&HARBOUR FAULTS'!K7 -> 21 | G37: =CONVERT(H37,"hr","min") -> 0 | H37: ='RTG&HARBOUR FAULTS'!N15 -> 0 | I37: =H37 -> 0 | J37: =I37/0.00069444444444444 -> 0 | K37: =(1-I37)/0.00069444444444444 -> 1440 | L37: =((1440-(J37))/1440)*100 -> 100 | M37: ='RTG&HARBOUR FAULTS'!O15 -> 0 | N37: =((1440-J37)/(M37+1))*0.00069444444444444 -> 1 | O37: =((1440-K37)/(M37))*0.00069444444444444 -> #DIV/0! | S37: =CONCATENATE("RTG17: ",'RTG&HARBOUR FAULTS'!B15,"_",'RTG&HARBOUR FAULTS'!F15,"_",'RTG&HARBOUR FAULTS'!J15) -> RTG17: NIL_NIL_NIL
C38: =AVERAGE(L64,L65,L66,L67,L68,L69,L70,L71,L72,L73,L74,L75,L76,L77,L78,L79,L80,L81,L82,L83) -> 78.854167 | G38: =CONVERT(H38,"hr","min") -> 60 | H38: ='RTG&HARBOUR FAULTS'!N16 -> 1 | I38: =H38 -> 1 | J38: =I38/0.00069444444444444 -> 1440 | K38: =(1-I38)/0.00069444444444444 -> 0 | L38: =((1440-(J38))/1440)*100 -> -6.3159354e-13 | M38: ='RTG&HARBOUR FAULTS'!O16 -> 0 | N38: =((1440-J38)/(M38+1))*0.00069444444444444 -> -6.3159354e-15 | O38: =((1440-K38)/(M38))*0.00069444444444444 -> #DIV/0! | S38: =CONCATENATE("RTG18: ",'RTG&HARBOUR FAULTS'!B16,"_",'RTG&HARBOUR FAULTS'!F16,"_",'RTG&HARBOUR FAULTS'!J16) -> RTG18: TRAVELLING.OUT_OUT_OUT
G39: =CONVERT(H39,"hr","min") -> 0 | H39: ='RTG&HARBOUR FAULTS'!N17 -> 0 | I39: =H39 -> 0 | J39: =I39/0.00069444444444444 -> 0 | K39: =(1-I39)/0.00069444444444444 -> 1440 | L39: =((1440-(J39))/1440)*100 -> 100 | M39: ='RTG&HARBOUR FAULTS'!O17 -> 0 | N39: =((1440-J39)/(M39+1))*0.00069444444444444 -> 1 | O39: =((1440-K39)/(M39))*0.00069444444444444 -> #DIV/0! | S39: =CONCATENATE("RTG19: ",'RTG&HARBOUR FAULTS'!B17,"_",'RTG&HARBOUR FAULTS'!F17,"_",'RTG&HARBOUR FAULTS'!J17) -> RTG19: REHABILITATION.OUT_OUT_OUT
G40: =CONVERT(H40,"hr","min") -> 60 | H40: ='RTG&HARBOUR FAULTS'!N18 -> 1 | I40: =H40 -> 1 | J40: =I40/0.00069444444444444 -> 1440 | K40: =(1-I40)/0.00069444444444444 -> 0 | L40: =((1440-(J40))/1440)*100 -> -6.3159354e-13 | M40: ='RTG&HARBOUR FAULTS'!O18 -> 0 | N40: =((1440-J40)/(M40+1))*0.00069444444444444 -> -6.3159354e-15 | O40: =((1440-K40)/(M40))*0.00069444444444444 -> #DIV/0! | S40: =CONCATENATE("RTG20: ",'RTG&HARBOUR FAULTS'!B18,"_",'RTG&HARBOUR FAULTS'!F18,"_",'RTG&HARBOUR FAULTS'!J18) -> RTG20: TROLLEY-OUT_OUT_OUT
...

Sheet Sheet31

Sheet Sheet30

Sheet Sheet1

Sheet Sheet21

Sheet Sheet22

Sheet Sheet23

Sheet Sheet24

Sheet Sheet25

Sheet Sheet26

Sheet Sheet19

Sheet Sheet20

Sheet Sheet14

Sheet Sheet6

Sheet Sheet15

Sheet Sheet4

Sheet Sheet13

Sheet Sheet11

Sheet Sheet9

Sheet Sheet2

Sheet Sheet29

Sheet Sheet3

Sheet Sheet32

Sheet Sheet28

Sheet Sheet16

Sheet Sheet10

Sheet Sheet7

Sheet Sheet8

Sheet Sheet17

Sheet Sheet12

Sheet STS RMG FAULTS
A1: 1 | C1: KENYA PORTS AUTHORITY
C2: CONTAINER TERMINAL ENGINEERING STS/RMG FAULTS AND DOWNTIME - | H2: 0700HRS
B3: ='OTHER REPORTS'!A3 -> TUESDAY 21ST OCTOBER 2025
B4: FIRST SHIFT | G4: SECOND SHIFT | K4: THIRD SHIFT | O4: TOTAL DOWNTIME PER EQUIPMENT | P4: TOTAL NO. OF CALLS PER DAY
A5: INCHARGE | C5: KOMBE | G5: AMUTI | K5: NDIRANGU
A6: AVAILED SHIFT @ END | B6: STS | C6: CONTAINER TERMINAL 1 | D6: 9 | G6: CONTAINER TERMINAL 1 | H6: 10 | K6: CONTAINER TERMINAL 1 | L6: 10
C7: CONTAINER TERMINAL 2 | D7: 5 | G7: CONTAINER TERMINAL 2 | H7: 5 | K7: CONTAINER TERMINAL 2 | L7: 5
A8: EQUIPMENT | B8: FAULT(S) | D8: DOWNTIME | E8: NO OF CALLS | G8: FAULT(S) | H8: DOWNTIME | I8: NO. OF CALLS | K8: FAULT(S) | L8: DOWNTIME | M8: NO. OF CALLS
A9: STS1603 | B9: HOIST | D9: 0 | E9: 10 | G9: NIL | H9: 0 | I9: 0 | K9: NIL | L9: 0 | M9: 0 | O9: =SUM(D9+H9+L9) -> 0 | P9: =E9+I9+M9 -> 10
A10: STS1604 | B10: NIL | D10: 0 | E10: 0 | G10: NIL | H10: 0 | I10: 0 | K10: NIL | L10: 0 | M10: 0 | O10: =SUM(D10+H10+L10) -> 0 | P10: 0
A11: STS1605 | B11: NIL | D11: 0 | E11: 0 | G11: NIL | H11: 0 | I11: 0 | K11: NIL | L11: 0 | M11: 0 | O11: =SUM(D11+H11+L11) -> 0 | P11: =E11+I11+M11 -> 0
A12: STS1606 | B12: NIL | D12: 0 | E12: 0 | G12: NIL | H12: 0 | I12: 0 | K12: NIL | L12: 0 | M12: 0 | O12: =SUM(D12+H12+L12) -> 0 | P12: =E12+I12+M12 -> 0
A13: STS1804 | B13: TRAVELLING | D13: 0.017361111 | E13: 1 | G13: TRAVELLING | H13: 0.010416667 | I13: 1 | K13: 40FT CONFIRMATION | L13: 0.010416667 | M13: 1 | O13: =SUM(D13+H13+L13) -> 0.038194444 | P13: =E13+I13+M13 -> 3
A14: STS1901 | B14: NIL | D14: 0 | E14: 0 | G14: NIL | H14: 0 | I14: 0 | K14: NIL | L14: 0 | M14: 0 | O14: =SUM(D14+H14+L14) -> 0 | P14: =E14+I14+M14 -> 0
A15: STS1902 | B15: NIL | D15: 0 | E15: 0 | G15: NIL | H15: 0 | I15: 0 | K15: NIL | L15: 0 | M15: 0 | O15: =SUM(D15+H15+L15) -> 0 | P15: =E15+I15+M15 -> 0
A16: STS1903 | B16: HOISTING/UMBILICAL SPRING/SLING SNAPPED | D16: 0.17013889 | E16: 2 | G16: UMBLICAL CABLE SPRING SNAPPED | H16: 0.017361111 | I16: 2 | K16: TRAVELLING | L16: 0.0034722222 | M16: 1 | O16: =SUM(D16+H16+L16) -> 0.19097222 | P16: =E16+I16+M16 -> 5
A17: STS1904 | B17: SPD COMMUNICATION | D17: 0.038194444 | E17: 2 | G17: NIL | H17: 0 | I17: 0 | K17: TWIN UP FAULT | L17: 0.0069444444 | M17: 1 | O17: =SUM(D17+H17+L17) -> 0.045138889 | P17: =E17+I17+M17 -> 3
A18: STS1905 | B18: HOIST WIRE ROPE SNAPPED | D18: 0.33333333 | E18: 0 | G18: READY AT 1610HRS/LOWERING | H18: 0.072916667 | I18: 1 | K18: CABLE REEL REEL SPRING SHACKLE SNAPPED | L18: 0.0069444444 | M18: 1 | O18: =SUM(D18+H18+L18) -> 0.41319444 | P18: =E18+I18+M18 -> 2
A19: STS2101 | B19: NIL | D19: 0 | E19: 0 | G19: LOCK SENSOR OFFSET/CARTENARY WIRE PULLEY DETACHED.OUT AT 1940HRS | H19: 0.14930556 | I19: 2 | K19: OUT | L19: 0.33333333 | M19: 0 | O19: =SUM(D19+H19+L19) -> 0.48263889 | P19: =E19+I19+M19 -> 2
A20: STS2102 | B20: NIL | D20: 0 | E20: 0 | G20: NIL | H20: 0 | I20: 0 | K20: NIL | L20: 0 | M20: 0 | O20: =SUM(D20+H20+L20) -> 0 | P20: =E20+H20+M20 -> 0
A21: STS2103 | B21: OP. CABIN DOOR REPAIR- AT 1105HRS | D21: 0.12152778 | E21: 1 | F21: 1 | G21: READY AT 1915HRS | H21: 0.17708333 | I21: 0 | K21: LOCK SIGNAL | L21: 0.020833333 | M21: 1 | O21: =SUM(D21+H21+L21) -> 0.31944444 | P21: =E21+I21+M21 -> 2
A22: STS2201 | B22: NIL | D22: 0 | E22: 0 | G22: NIL | H22: 0 | I22: 0 | K22: NIL | L22: 0 | M22: 0 | O22: =SUM(D22+H22+L22) -> 0 | P22: =E22+I22+M22 -> 0
A23: STS2202 | B23: NIL | D23: 0 | E23: 0 | G23: NIL | H23: 0 | I23: 0 | K23: NIL | L23: 0 | M23: 0 | O23: =SUM(D23+H23+L23) -> 0 | P23: =E23+I23+M23 -> 0
A24: STS2203 | B24: NIL | D24: 0 | E24: 0 | G24: NIL | H24: 0 | I24: 0 | K24: NIL | L24: 0 | M24: 0 | O24: =SUM(D24+H24+L24) -> 0 | P24: =E24+I24+M24 -> 0
A25: TOTAL DOWN TIME PER SHIFT | B25: ; | D25: =SUM(D9:D24) -> 0.68055556 | H25: =SUM(H9:H24) -> 0.42708333 | L25: =SUM(L9:L24) -> 0.38194444 | M25: 0
C26: =C5 -> KOMBE | G26: =G5 -> AMUTI | K26: =K5 -> NDIRANGU | M26: 0 | O26: =SUM(O9:O24) -> 1.4895833
A27: AVAILED SHIFT @ END | B27: RMG | C27: TERMINAL 1 | D27: 5 | G27: TERMINAL 1 | H27: 5 | K27: TERMINAL 1 | L27: 5 | M27: 0
C28: TERMINAL 2 | D28: 2 | G28: TERMINAL 2 | H28: 2 | K28: TERMINAL 2 | L28: 2 | M28: 0
A29: RMG05 | B29: CONTROL ON -OUT | D29: 0.33333333 | E29: 0 | G29: OUT | H29: 0.33333333 | I29: 0 | K29: OUT | L29: 0.33333333 | M29: 0 | O29: =SUM(D29+H29+L29) -> 1 | P29: =E29+I29+M29 -> 0
A30: RMG06 | B30: NIL | D30: 0 | E30: 0 | G30: NIL | H30: 0 | I30: 0 | K30: SLOW MOTION | L30: 0.048611111 | M30: 1 | O30: =SUM(D30+H30+L30) -> 0.048611111 | P30: =E30+I30+M30 -> 1
A31: RMG07 | B31: NIL | D31: 0 | E31: 0 | G31: NIL | H31: 0 | I31: 0 | K31: NIL | L31: 0 | M31: 0 | O31: =SUM(D31+H31+L31) -> 0 | P31: =E31+I31+M31 -> 0
A32: RMG08 | B32: NIL | D32: 0 | E32: 0 | G32: NIL | H32: 0 | I32: 0 | K32: NIL | L32: 0 | M32: 0 | O32: =SUM(D32+H32+L32) -> 0 | P32: =E32+I32+M32 -> 0
A33: RMG09 | B33: NIL | D33: 0 | E33: 0 | G33: NIL | H33: 0 | I33: 0 | K33: NIL | L33: 0 | M33: 0 | O33: =SUM(D33+H33+L33) -> 0 | P33: =E33+I33+M33 -> 0
A34: RMG10 | B34: NIL | D34: 0 | E34: 0 | G34: NIL | H34: 0 | I34: 0 | K34: NIL | L34: 0 | M34: 0 | O34: =SUM(D34+H34+L34) -> 0 | P34: =E34+I34+M34 -> 0
A35: RMG2-11 | B35: NIL | D35: 0 | E35: 0 | G35: NIL | H35: 0 | I35: 0 | K35: NIL | L35: 0 | M35: 0 | O35: =SUM(D35+H35+L35) -> 0 | P35: =E35+I35+M35 -> 0
A36: RMG2-12 | B36: NIL | D36: 0 | E36: 0 | G36: NIL | H36: 0 | I36: 0 | K36: NIL | L36: 0 | M36: 0 | O36: =SUM(D36+H36+L36) -> 0 | P36: =E36+I36+M36 -> 0
A37: TOTAL DOWN TIME PER SHIFT | D37: =SUM(D29:D36) -> 0.33333333 | H37: =SUM(H29:H36) -> 0.33333333 | L37: =SUM(L29:L36) -> 0.38194444 | M37: 0 | O37: =SUM(O29:O36) -> 1.0486111
C38: =C5 -> KOMBE | G38: =G5 -> AMUTI | K38: =K5 -> NDIRANGU | O38: =O37*60 -> 62.916667

Sheet RTG&HARBOUR FAULTS
B1: KENYA PORTS AUTHORITY
B2: CONTAINER TERMINAL ENGINEERING RTG FAULTS AND DOWNTIME - | G2: 0700HRS
B3: ='OTHER REPORTS'!A3 -> TUESDAY 21ST OCTOBER 2025
B4: FIRST SHIFT | F4: SECOND SHIFT | J4: THIRD SHIFT | N4: TOTAL DOWNTIME PER EQUIPMENT | O4: TOTAL NO. OF CALLS PER DAY
A5: INCHARGE | B5: ='STS RMG FAULTS'!C5 -> KOMBE | F5: ='STS RMG FAULTS'!G5 -> AMUTI | J5: ='STS RMG FAULTS'!K5 -> NDIRANGU
A6: 61 | B6: TERMINAL 1 | C6: 23 | F6: TERMINAL 1 | G6: 23 | J6: TERMINAL 1 | K6: 22
B7: TERMINAL 2 | C7: 21 | F7: TERMINAL 2 | G7: 21 | J7: TERMINAL 2 | K7: 21
A8: 1 | B8: MOBILE HARBOUR CRANE | C8: 2 | F8: MOBILE HARBOUR CRANE | G8: 2 | J8: MOBILE HARBOUR CRANE | K8: 2
A9: EQUIPMENT | B9: FAULT(S) | C9: DOWNTIME | D9: NO. OF CALLS | F9: FAULT(S) | G9: DOWNTIME | H9: NO. OF CALLS | J9: FAULT(S) | K9: DOWNTIME | L9: NO. OF CALLS
A10: RTG12 | B10: NIL | C10: 0 | D10: 0 | F10: NIL | G10: 0 | H10: 0 | J10: NIL | K10: 0 | L10: 0 | N10: =SUM(C10+G10+K10) -> 0 | O10: =D10+H10+L10 -> 0
A11: RTG13 | B11: NIL | C11: 0 | D11: 0 | F11: NIL | G11: 0 | H11: 0 | I11: 0 | J11: NIL | K11: 0 | L11: 0 | N11: =SUM(C11+G11+K11) -> 0 | O11: =D11+H11+L11 -> 0
A12: RTG14 | B12: NIL | C12: 0 | D12: 0 | F12: NIL | G12: 0 | H12: 0 | J12: NIL | K12: 0 | L12: 0 | N12: =SUM(C12+G12+K12) -> 0 | O12: =D12+H12+L12 -> 0
A13: RTG15 | B13: NIL | C13: 0 | D13: 0 | F13: NIL | G13: 0 | H13: 0 | J13: NIL | K13: 0 | L13: 0 | N13: =SUM(C13+G13+K13) -> 0 | O13: =D13+H13+L13 -> 0
A14: RTG16 | B14: NIL | C14: 0 | D14: 0 | F14: NIL | G14: 0 | H14: 0 | J14: NIL | K14: 0 | L14: 0 | N14: =SUM(C14+G14+K14) -> 0 | O14: =D14+H14+L14 -> 0
A15: RTG17 | B15: NIL | C15: 0 | D15: 0 | F15: NIL | G15: 0 | H15: 0 | J15: NIL | K15: 0 | L15: 0 | N15: =SUM(C15+G15+K15) -> 0 | O15: =D15+H15+L15 -> 0
A16: RTG18 | B16: TRAVELLING.OUT | C16: 0.33333333 | D16: 0 | F16: OUT | G16: 0.33333333 | H16: 0 | J16: OUT | K16: 0.33333333 | L16: 0 | N16: =SUM(C16+G16+K16) -> 1 | O16: =D16+H16+L16 -> 0
A17: RTG19 | B17: REHABILITATION.OUT | C17: 0 | D17: 0 | F17: OUT | G17: 0 | H17: 0 | J17: OUT | K17: 0 | L17: 0 | N17: =SUM(C17+G17+K17) -> 0 | O17: =D17+H17+L17 -> 0
A18: RTG20 | B18: TROLLEY-OUT | C18: 0.33333333 | D18: 0 | F18: OUT | G18: 0.33333333 | H18: 0 | J18: OUT | K18: 0.33333333 | L18: 0 | N18: =SUM(C18+G18+K18) -> 1 | O18: =D18+H18+L18 -> 0
A19: RTG21 | B19: NIL | C19: 0 | D19: 0 | F19: NIL | G19: 0 | H19: 0 | J19: NIL | K19: 0 | L19: 0 | N19: =SUM(C19+G19+K19) -> 0 | O19: =D19+H19+L19 -> 0
A20: RTG22 | B20: ENGINE STARTING-OUT | C20: 0.33333333 | D20: 0 | F20: OUT | G20: 0.33333333 | H20: 0 | J20: OUT | K20: 0.33333333 | L20: 0 | N20: =SUM(C20+G20+K20) -> 1 | O20: =D20+H20+L20 -> 0
A21: RTG23 | B21: ENGINE STARTING-OUT | C21: 0.33333333 | D21: 0 | F21: OUT | G21: 0.33333333 | H21: 0 | J21: OUT | K21: 0.33333333 | L21: 0 | N21: =SUM(C21+G21+K21) -> 1 | O21: =D21+H21+L21 -> 0
A22: RTG24 | B22: LOW TYRE PRESSURE | C22: 0.14583333 | D22: 1 | F22: NIL | G22: 0 | H22: 0 | J22: NIL | K22: 0 | L22: 0 | M22: 1 | N22: =SUM(C22+G22+K22) -> 0.14583333 | O22: =D22+H22+L22 -> 1
A23: RTG25 | B23: NIL | C23: 0 | D23: 0 | F23: NIL | G23: 0 | H23: 0 | J23: NIL | K23: 0 | L23: 0 | N23: =SUM(C23+G23+K23) -> 0 | O23: =D23+H23+L23 -> 0
A24: RTG26 | B24: NIL | C24: 0 | D24: 0 | F24: NIL | G24: 0 | H24: 0 | J24: NIL | K24: 0 | L24: 0 | N24: =SUM(C24+G24+K24) -> 0 | O24: =D24+H24+L24 -> 0
A25: RTG27 | B25: ENGINE STARTING | C25: 0.013888889 | D25: 1 | F25: NIL | G25: 0 | H25: 0 | J25: DIESEL LEAKAGE/ LOCK SIGNAL | K25: 0.017361111 | L25: 2 | N25: =SUM(C25+G25+K25) -> 0.03125 | O25: =D25+H25+L25 -> 3
A26: RTG28 | B26: NIL | C26: 0 | D26: 0 | F26: NIL | G26: 0 | H26: 0 | J26: ACCIDENT-STEERED INTO CONTAINERS-OUT@ 0120HRS | K26: 0.23611111 | L26: 1 | N26: =SUM(C26+G26+K26) -> 0.23611111 | O26: =D26+H26+L26 -> 1
A27: RTG29 | B27: NIL | C27: 0 | D27: 0 | F27: NIL | G27: 0 | H27: 0 | J27: NIL | K27: 0 | L27: 0 | N27: =SUM(C27+G27+K27) -> 0 | O27: =D27+H27+L27 -> 0
A28: RTG30 | B28: HOIST DRIVE -OUT | C28: 0.33333333 | D28: 0 | F28: OUT | G28: 0.33333333 | H28: 0 | J28: OUT | K28: 0.33333333 | L28: 0 | N28: =SUM(C28+G28+K28) -> 1 | O28: =D28+H28+L28 -> 0
A29: RTG31 | B29: GANTRY MOTOR SHORT CCT FLT -OUT | C29: 0.33333333 | D29: 0 | F29: OUT | G29: 0.33333333 | H29: 0 | J29: OUT | K29: 0.33333333 | L29: 0 | N29: =SUM(C29+G29+K29) -> 1 | O29: =D29+H29+L29 -> 0
A30: RTG32 | B30: NIL | C30: 0 | D30: 0 | F30: NIL | G30: 0 | H30: 0 | J30: NIL | K30: 0 | L30: 0 | N30: =SUM(C30+G30+K30) -> 0 | O30: =D30+H30+L30 -> 0
A31: RTG33 | B31: GENERATOR VIBRATIONS.OUT | C31: 0.33333333 | D31: 0 | F31: OUT | G31: 0.33333333 | H31: 0 | J31: OUT | K31: 0.33333333 | L31: 0 | N31: =SUM(C31+G31+K31) -> 1 | O31: =D31+H31+L31 -> 0
A32: RTG34 | B32: NIL | C32: 0 | D32: 0 | E32: 1 | F32: NIL | G32: 0 | H32: 0 | J32: NIL | K32: 0 | L32: 0 | N32: =SUM(C32+G32+K32) -> 0 | O32: =D32+H32+L32 -> 0
A33: RTG35 | B33: ACCIDENTCABLE VANDALISED - OUT | C33: 0.33333333 | D33: 0 | F33: OUT | G33: 0.33333333 | H33: 0 | J33: OUT | K33: 0.33333333 | L33: 0 | N33: =SUM(C33+G33+K33) -> 1 | O33: =D33+H33+L33 -> 0
A34: RTG36 | B34: NIL | C34: 0 | D34: 0 | F34: NIL | G34: 0 | H34: 0 | J34: NIL | K34: 0 | L34: 0 | N34: =SUM(C34+G34+K34) -> 0 | O34: =D34+H34+L34 -> 0
A35: RTG37 | B35: NIL | C35: 0 | D35: 0 | F35: NIL | G35: 0 | H35: 0 | J35: NIL | K35: 0 | L35: 0 | N35: =SUM(C35+G35+K35) -> 0 | O35: =D35+H35+L35 -> 0
A36: RTG38 | B36: NIL | C36: 0 | D36: 0 | F36: LOCK SIGNAL | G36: 0.03125 | H36: 1 | J36: NIL | K36: 0 | L36: 0 | N36: =SUM(C36+G36+K36) -> 0.03125 | O36: =D36+H36+L36 -> 1
A37: RTG39 | B37: ENGINE STARTING/CABLES VANDALISED-OUT | C37: 0.33333333 | D37: 0 | F37: OUT | G37: 0.33333333 | H37: 0 | J37: OUT | K37: 0.33333333 | L37: 0 | N37: =SUM(C37+G37+K37) -> 1 | O37: =D37+H37+L37 -> 0
A38: RTG41 | B38: CONTROL ON | C38: 0.0069444444 | D38: 1 | E38: 1 | F38: STARTING | G38: 0.024305556 | H38: 1 | J38: NIL | K38: 0 | L38: 0 | M38: 0 | N38: =SUM(C38+G38+K38) -> 0.03125 | O38: =D38+H38+L38 -> 2
A39: RTG42 | B39: NIL | C39: 0 | D39: 0 | F39: NIL | G39: 0 | H39: 0 | J39: NIL | K39: 0 | L39: 0 | N39: =SUM(C39+G39+K39) -> 0 | O39: =D39+H39+L39 -> 0
A40: RTG44 | B40: NIL | C40: 0 | D40: 0 | F40: NIL | G40: 0 | H40: 0 | J40: NIL | K40: 0 | L40: 0 | N40: =SUM(C40+G40+K40) -> 0 | O40: =D40+H40+L40 -> 0
...

Sheet CONTAINER HANDLERS FAULTS
C1: KENYA PORTS AUTHORITY | N1: 1 | FDV1: A1
C2: CONTAINER TERMINAL REACHSTACKERS AND EMPTY CONTAINER HANDLERS FAULTS AND DOWNTIME
B3: ='OTHER REPORTS'!A3 -> TUESDAY 21ST OCTOBER 2025
C4: FIRST SHIFT | G4: SECOND SHIFT | K4: THIRD SHIFT | O4: TOTAL DOWNTIME PER EQUIPMENT | P4: TOTAL NO. OF CALLS PER DAY
A5: INCHARGE | C5: ='STS RMG FAULTS'!C5 -> KOMBE | G5: ='STS RMG FAULTS'!G5 -> AMUTI | K5: ='STS RMG FAULTS'!K5 -> NDIRANGU
A6: AVAILED SHIFT @ END | B6: R/S | C6: 10 | G6: 10 | K6: 10
B7: ECH | C7: TERMINAL 1 | D7: 7 | G7: TERMINAL 1 | H7: 7 | K7: TERMINAL 1 | L7: 7
C8: TERMINAL 2 | D8: 7 | G8: TERMINAL 2 | H8: 7 | K8: TERMINAL 2 | L8: 6
A9: EQUIPMENT | D9: DOWNTIME | E9: NO. OF CALLS | G9: FAULT(S) | H9: DOWNTIME | I9: NO. OF CALLS | K9: FAULT(S) | L9: DOWNTIME | M9: NO. OF CALLS
A10: HK39 | B10: RADIATOR LEAKAGES -OUT | D10: 0.33333333 | E10: 0 | G10: OUT | H10: 0.33333333 | I10: 0 | K10: OUT | L10: 0.33333333 | M10: 0 | O10: =SUM(D10+H10+L10) -> 1 | P10: =E10+I10+M10 -> 0
A11: HK40 | B11: HYD OIL LEAKAGE | D11: 0.079861111 | E11: 1 | G11: NIL | H11: 0 | I11: 0 | K11: NIL | L11: 0 | M11: 0 | O11: =SUM(D11+H11+L11) -> 0.079861111 | P11: =E11+I11+M11 -> 1
A12: HK41 | B12: COMMUNICATION - OUT | D12: 0.33333333 | E12: 0 | G12: OUT | H12: 0.33333333 | I12: 0 | K12: OUT | L12: 0.33333333 | M12: 0 | O12: =SUM(D12+H12+L12) -> 1 | P12: =E12+I12+M12 -> 0
A13: HK42 | B13: NIL | D13: 0 | E13: 0 | G13: NIL | H13: 0 | I13: 0 | K13: NIL | L13: 0 | M13: 0 | O13: =SUM(D13+H13+L13) -> 0 | P13: =E13+I13+M13 -> 0
A14: HK43 | B14: NIL | D14: 0 | E14: 0 | G14: NIL | H14: 0 | I14: 0 | K14: NIL | L14: 0 | M14: 0 | O14: =SUM(D14+H14+L14) -> 0 | P14: =E14+I14+M14 -> 0
A15: HK44 | B15: ENGINE OVERHEATING-OUT | D15: 0.33333333 | E15: 0 | G15: OUT | H15: 0.33333333 | I15: 0 | K15: OUT | L15: 0.33333333 | M15: 0 | O15: =SUM(D15+H15+L15) -> 1 | P15: =E15+I15+M15 -> 0
A16: HK45 | B16: STEERING CYLINDER PIN OFF-OUT | D16: 0.33333333 | E16: 0 | G16: OUT | H16: 0.33333333 | I16: 0 | K16: OUT | L16: 0.33333333 | M16: 0 | O16: =SUM(D16+H16+L16) -> 1 | P16: =E16+I16+M16 -> 0
A17: HK46 | B17: TRANSMISSION FAULT.OUT | D17: 0.33333333 | E17: 0 | G17: OUT | H17: 0.33333333 | I17: 0 | K17: OUT | L17: 0.33333333 | M17: 0 | O17: =SUM(D17+H17+L17) -> 1 | P17: =E17+I17+M17 -> 0
A18: HK48 | B18: NIL | D18: 0 | E18: 0 | G18: NIL | H18: 0 | I18: 0 | K18: NIL | L18: 0 | M18: 0 | O18: =SUM(D18+H18+L18) -> 0 | P18: =E18+I18+M18 -> 0
A19: HK49 | B19: GEAR FAULT-OUT | D19: 0.33333333 | E19: 0 | G19: OUT | H19: 0.33333333 | I19: 0 | K19: OUT | L19: 0.33333333 | M19: 0 | O19: =SUM(D19+H19+L19) -> 1 | P19: =E19+I19+M19 -> 0
A20: HK50 | B20: NIL | D20: 0 | E20: 0 | G20: NIL | H20: 0 | I20: 0 | K20: NIL | L20: 0 | M20: 0 | O20: =SUM(D20+H20+L20) -> 0 | P20: =E20+I20+M20 -> 0
A21: HK52 | B21: NIL | D21: 0 | E21: 0 | G21: NIL | H21: 0 | I21: 0 | K21: NIL | L21: 0 | M21: 0 | O21: =SUM(D21+H21+L21) -> 0 | P21: =E21+I21+M21 -> 0
... A23: HK54 | B23: STARTING-READY AT 1230HRS | D23: 0.22916667 | E23: 0 | G23: STARTING | H23: 0.041666667 | I23: 1 | K23: STEERING PROBLEM-OUT@ 2350HRS | L23: 0.29861111 | M23: 1 | O23: =SUM(D23+H23+L23) -> 0.56944444 | P23: =E23+I23+M23 -> 2
A24: HK55 | B24: NIL | D24: 0 | E24: 0 | G24: NIL | H24: 0 | I24: 0 | K24: NIL | L24: 0 | M24: 0 | N24: 1 | O24: =SUM(D24+H24+L24) -> 0 | P24: =E24+I24+M24 -> 0
A25: HK56 | B25: NIL | D25: 0 | E25: 0 | G25: NIL | H25: 0 | I25: 0 | K25: NIL | L25: 0 | M25: 0 | O25: =SUM(D25+H25+L25) -> 0 | P25: =E25+I25+M25 -> 0
A26: HK57 | B26: SPD LOCK PIN -OUT | D26: 0.33333333 | E26: 0 | G26: OUT | H26: 0.33333333 | I26: 0 | K26: OUT | L26: 0.33333333 | M26: 0 | O26: =SUM(D26+H26+L26) -> 1 | P26: =E26+I26+M26 -> 0
A27: HH33 | B27: GEAR FAULT-OUT | D27: 0.33333333 | E27: 0 | G27: OUT | H27: 0.33333333 | I27: 0 | K27: OUT | L27: 0.33333333 | M27: 0 | O27: =SUM(D27+H27+L27) -> 1 | P27: =E27+I27+M27 -> 0
A28: HH35 | B28: NO MOTIONS-OUT | D28: 0.33333333 | E28: 0 | G28: OUT | H28: 0.33333333 | I28: 0 | K28: OUT | L28: 0.33333333 | M28: 0 | O28: =SUM(D28+H28+L28) -> 1 | P28: =E28+I28+M28 -> 0
D29: 0 | E29: 0 | H29: =SUM(H7:H8) -> 14 | I29: 0 | K29: NIL | M29: 0 | O29: =SUM(D29+H29+L29) -> 14 | P29: =E29+I29+M29 -> 0
A30: TOTAL DOWN TIME PER SHIFT | D30: =SUM(D10:D28) -> 3.3090278 | H30: =SUM(H10:H28) -> 3.0416667 | L30: =SUM(L10:L28) -> 3.2986111 | O30: =SUM(O10:O28) -> 9.6493056
A31: ECH07 | B31: REVERSE GEAR FAULT-OUT | D31: 0.33333333 | E31: 0 | G31: OUT | H31: 0.33333333 | I31: 0 | K31: OUT | L31: 0.33333333 | M31: 0 | O31: =SUM(D31+H31+L31) -> 1 | P31: =E31+I31+M31 -> 0
A32: ECH09 | B32: LOW ENGINE POWER-OUT | D32: 0.33333333 | E32: 0 | G32: OUT | H32: 0.33333333 | I32: 0 | K32: OUT | L32: 0.33333333 | M32: 0 | O32: =SUM(D32+H32+L32) -> 1 | P32: =E32+I32+M32 -> 0
A33: ECH12 | B33: NIL | D33: 0 | E33: 0 | G33: NIL | H33: 0 | I33: 0 | K33: NIL | L33: 0 | M33: 0 | O33: =SUM(D33+H33+L33) -> 0 | P33: =E33+I33+M33 -> 0
A34: ECH14 | B34: LOCK SIGNAL -OUT | D34: 0.33333333 | E34: 0 | G34: OUT | H34: 0.33333333 | I34: 0 | K34: OUT | L34: 0.33333333 | M34: 0 | O34: =SUM(D34+H34+L34) -> 1 | P34: =E34+I34+M34 -> 0
A35: ECH17 | B35: COMMUNICATION/ ENGINE STARTING -OUT | D35: 0.33333333 | E35: 0 | G35: OUT | H35: 0.33333333 | I35: 0 | K35: OUT | L35: 0.33333333 | M35: 0 | O35: =SUM(D35+H35+L35) -> 1 | P35: =E35+I35+M35 -> 0
A36: ECH18 | B36: BRAKE OIL LEAK - OUT | D36: 0.33333333 | E36: 0 | G36: OUT | H36: 0.33333333 | I36: 0 | K36: OUT | L36: 0.33333333 | M36: 0 | O36: =SUM(D36+H36+L36) -> 1 | P36: =E36+I36+M36 -> 0
A37: ECH19 | B37: NIL | D37: 0 | E37: 0 | G37: NIL | H37: 0 | I37: 0 | K37: NIL | L37: 0 | M37: 0 | O37: =SUM(D37+H37+L37) -> 0 | P37: =E37+H37+M37 -> 0
A38: ECH20 | B38: CAN BUS-OUT | D38: 0.33333333 | E38: 0 | G38: OUT | H38: 0.33333333 | I38: 0 | K38: OUT | L38: 0.33333333 | M38: 0 | O38: =SUM(D38+H38+L38) -> 1 | P38: =E38+I38+M38 -> 0
A39: ECH21 | B39: NIL | D39: 0 | E39: 0 | G39: NIL | H39: 0 | I39: 0 | K39: NIL | L39: 0 | M39: 0 | O39: =SUM(D39+H39+L39) -> 0 | P39: =E39+I39+M39 -> 0
A40: ECH22 | B40: LOCK SIGNAL | D40: 0.010416667 | E40: 1 | G40: NIL | H40: 0 | I40: 0 | K40: NIL | L40: 0 | M40: 0 | O40: =SUM(D40+H40+L40) -> 0.010416667 | P40: =E40+I40+M40 -> 1
A41: ECH23 | B41: NIL | D41: 0 | E41: 0 | G41: NIL | H41: 0 | I41: 0 | K41: LOW BATTERY-OUT@0610HRS | L41: 0.034722222 | M41: 1 | O41: =SUM(D41+H41+L41) -> 0.034722222 | P41: =E41+I41+M41 -> 1
...

Sheet TERMINAL TRACTORS
A1: CONTAINER TERMINAL ENGINEERING TERMINAL TRACTORS & TRAILERS FAULTS AND DOWNTIME
B2: ='OTHER REPORTS'!A3 -> TUESDAY 21ST OCTOBER 2025
B3: FIRST SHIFT | F3: SECOND SHIFT | J3: THIRD SHIFT
A4: INCHARGE | B4: ='STS RMG FAULTS'!C5 -> KOMBE | F4: ='STS RMG FAULTS'!G5 -> AMUTI | J4: ='STS RMG FAULTS'!K5 -> NDIRANGU
A5: AVAILED PER SHIFT | C5: AVAILABLE | D5: B/DOWN | G5: AVAILABLE | H5: B/DOWN | K5: AVAILABLE | L5: B/DOWN | M5: TOTAL DOWNTIME PER EQUIPMENT | N5: TOTAL CALLS
B6: TERMINAL TRACTORS | C6: 86 | D6: =102-C6 -> 16 | G6: 85 | H6: =102-G6 -> 17 | J6: TERMINAL TRACTORS | K6: 85 | L6: =102-K6 -> 17 | M6: =K6 -> 85
B7: TRAILERS | C7: 131 | D7: =(141-C7) -> 10 | F7: TRAILERS | G7: 129 | H7: =(141-G7) -> 12 | J7: TRAILERS | K7: 129 | L7: =(141-K7) -> 12 | M7: =K7 -> 129
A8: TT | B8: FAULT(S) | C8: DOWNTIME | D8: NO. OF CALLS | F8: FAULT(S) | G8: DOWNTIME | H8: NO. OF CALLS | J8: FAULT(S) | K8: DOWNTIME | L8: NO. OF CALLS
A9: MRTT108 | B9: BRAKES -OUT | C9: 0.33333333 | D9: 0 | F9: OUT | G9: 0.33333333 | H9: 0 | J9: OUT | K9: 0.33333333 | L9: 0 | M9: =SUM(C9,G9,K9) -> 1 | N9: =D9+H9+L9 -> 0
A10: MRTT109 | B10: 24V SHORT CIRCUIT -OUT | C10: 0.33333333 | D10: 0 | F10: OUT | G10: 0.33333333 | H10: 0 | J10: OUT | K10: 0.33333333 | L10: 0 | M10: =SUM(C10,G10,K10) -> 1 | N10: =D10+H10+L10 -> 0
A11: MRTT110 | B11: BRAKES -OUT | C11: 0.33333333 | D11: 0 | F11: OUT | G11: 0.33333333 | H11: 0 | J11: OUT | K11: 0.33333333 | L11: 0 | M11: =SUM(C11,G11,K11) -> 1 | N11: =D11+H11+L11 -> 0
A12: MRTT111 | B12: NIL | C12: 0 | D12: 0 | F12: NIL | G12: 0 | H12: 0 | J12: NIL | K12: 0 | L12: 0 | M12: =SUM(C12,G12,K12) -> 0 | N12: =D12+H12+L12 -> 0
A13: MRTT113 | B13: FLY WHEEL RING GEAR FAULT-OUT | C13: 0.33333333 | D13: 0 | F13: OUT | G13: 0.33333333 | H13: 0 | J13: OUT | K13: 0.33333333 | L13: 0 | M13: =SUM(C13,G13,K13) -> 1 | N13: =D13+H13+L13 -> 0
A14: MRTT114 | B14: ACCIDENT-OUT | C14: 0.33333333 | D14: 0 | F14: OUT | G14: 0.33333333 | H14: 0 | J14: OUT | K14: 0.33333333 | L14: 0 | M14: =SUM(C14,G14,K14) -> 1 | N14: =D14+H14+L14 -> 0
A15: MRTT116 | B15: 5TH WHEEL -OUT | C15: 0.33333333 | D15: 0 | F15: OUT | G15: 0.33333333 | H15: 0 | J15: OUT | K15: 0.33333333 | L15: 0 | M15: =SUM(C15,G15,K15) -> 1 | N15: =D15+H15+L15 -> 0
A16: MRTT118 | B16: NIL | C16: 0 | D16: 0 | F16: STEERING HYDRAULIC OIL PIPE LEAKAGE.OUT AT 1515HRS | G16: 0.32291667 | H16: 1 | J16: OUT | K16: 0.33333333 | L16: 0 | M16: =SUM(C16,G16,K16) -> 0.65625 | N16: =D16+H16+L16 -> 1
A17: MRTT121 | B17: FLY WHEEL RING GEAR FAULT- OUT | C17: 0.33333333 | D17: 0 | F17: OUT | G17: 0.33333333 | H17: 0 | J17: OUT | K17: 0.33333333 | L17: 0 | M17: =SUM(C17,G17,K17) -> 1 | N17: =D17+H17+L17 -> 0
A18: MRTT122 | B18: STEERING LOCK -OUT | C18: 0.33333333 | D18: 0 | F18: OUT | G18: 0.33333333 | H18: 0 | J18: OUT | K18: 0.33333333 | L18: 0 | M18: =SUM(C18,G18,K18) -> 1 | N18: =D18+H18+L18 -> 0
A19: MRTT123 | B19: FAULTY REAR BRAKES - OUT | C19: 0.33333333 | D19: 0 | F19: OUT | G19: 0.33333333 | H19: 0 | J19: OUT | K19: 0.33333333 | L19: 0 | M19: =SUM(C19,G19,K19) -> 1 | N19: 0
A20: MRTT124 | B20: FLY WHEEL RING GEAR FAULT- OUT | C20: 0.33333333 | D20: 0 | F20: OUT | G20: 0.33333333 | H20: 0 | J20: OUT | K20: 0.33333333 | L20: 0 | M20: =SUM(C20,G20,K20) -> 1 | N20: =D20+H20+L20 -> 0
A21: KTT191 | B21: FAULTY HYDRAULIC CONTROL VALVE - OUT | C21: 0.33333333 | D21: 0 | F21: OUT | G21: 0.33333333 | H21: 0 | J21: OUT | K21: 0.33333333 | L21: 0 | M21: =SUM(C21,G21,K21) -> 1 | N21: =D21+H21+L21 -> 0
A22: KTT192 | B22: NIL | C22: 0 | D22: 0 | F22: NIL | G22: 0 | H22: 0 | J22: NIL | K22: 0 | L22: 0 | M22: =SUM(C22,G22,K22) -> 0 | N22: =D22+H22+L22 -> 0
A23: KTT193 | B23: 5TH WHEEL -OUT | C23: 0.33333333 | D23: 0 | E23: N | F23: OUT | G23: 0.33333333 | H23: 0 | J23: OUT | K23: 0.33333333 | L23: 0 | M23: =SUM(C23,G23,K23) -> 1 | N23: =D23+H23+L23 -> 0
A24: KTT194 | B24: LEAF SPRING DETACHED-OUT | C24: 0.33333333 | D24: 0 | F24: OUT | G24: 0.33333333 | H24: 0 | J24: OUT | K24: 0.33333333 | L24: 0 | M24: =SUM(C24,G24,K24) -> 1 | N24: =D24+H24+L24 -> 0
A25: KTT197 | B25: FAULTY HYDRAULIC CONTROL VALVE - OUT | C25: 0.33333333 | D25: 0 | E25: 0 | F25: OUT | G25: 0.33333333 | H25: 0 | J25: OUT | K25: 0.33333333 | L25: 0 | M25: =SUM(C25,G25,K25) -> 1 | N25: =D25+H25+L25 -> 0
A26: KTT199 | B26: NIL | C26: 0 | D26: 0 | F26: NIL | G26: 0 | H26: 0 | J26: NIL | K26: 0 | L26: 0 | M26: =SUM(C26,G26,K26) -> 0 | N26: =D26+H26+L26 -> 0
A27: KTT200 | B27: NIL | C27: 0 | D27: 0 | F27: NIL | G27: 0 | H27: 0 | J27: NIL | K27: 0 | L27: 0 | M27: =SUM(C27,G27,K27) -> 0 | N27: =D27+H27+L27 -> 0
A28: KTT202 | B28: NIL | C28: 0 | D28: 0 | F28: NIL | G28: 0 | H28: 0 | J28: NIL | K28: 0 | L28: 0 | M28: =SUM(C28,G28,K28) -> 0 | N28: =D28+H28+L28 -> 0
A29: KTT203 | B29: UNSUAL NOISE -OUT | C29: 0.33333333 | D29: 0 | F29: OUT | G29: 0.33333333 | H29: 0 | J29: OUT | K29: 0.33333333 | L29: 0 | M29: =SUM(C29,G29,K29) -> 1 | N29: =D29+H29+L29 -> 0
A30: KTT204 | B30: NIL | C30: 0 | D30: 0 | F30: NIL | G30: 0 | H30: 0 | J30: NIL | K30: 0 | L30: 0 | M30: =SUM(C30,G30,K30) -> 0 | N30: =D30+H30+L30 -> 0
A31: KTT211 | B31: NIL | C31: 0 | D31: 0 | F31: NIL | G31: 0 | H31: 0 | J31: NIL | K31: 0 | L31: 0 | M31: =SUM(C31,G31,K31) -> 0 | N31: =D31+H31+L31 -> 0
A32: KTT212 | B32: REAR DRIVE AXLE FAULT.OUT | C32: 0.33333333 | D32: 0 | F32: OUT | G32: 0.33333333 | H32: 0 | J32: OUT | K32: 0.33333333 | L32: 0 | M32: =SUM(C32,G32,K32) -> 1 | N32: =D32+H32+L32 -> 0
A33: KTT213 | B33: NIL | C33: 0 | D33: 0 | F33: NIL | G33: 0 | H33: 0 | J33: NIL | K33: 0 | L33: 0 | M33: =SUM(C33,G33,K33) -> 0 | N33: =D33+H33+L33 -> 0
A34: KTT214 | B34: NIL | C34: 0 | D34: 0 | F34: NIL | G34: 0 | H34: 0 | J34: NIL | K34: 0 | L34: 0 | M34: =SUM(C34,G34,K34) -> 0 | N34: =D34+H34+L34 -> 0
A35: KTT215 | B35: NIL | C35: 0 | D35: 0 | F35: NIL | G35: 0 | H35: 0 | J35: NIL | K35: 0 | L35: 0 | M35: =SUM(C35,G35,K35) -> 0 | N35: =D35+H35+L35 -> 0
A36: KTT216 | B36: NIL | C36: 0 | D36: 0 | F36: NIL | G36: 0 | H36: 0 | J36: NIL | K36: 0 | L36: 0 | M36: =SUM(C36,G36,K36) -> 0 | N36: =D36+H36+L36 -> 0
A37: KTT217 | B37: NIL | C37: 0 | D37: 0 | F37: NIL | G37: 0 | H37: 0 | J37: NIL | K37: 0 | L37: 0 | M37: =SUM(C37,G37,K37) -> 0 | N37: =D37+H37+L37 -> 0
... A96: TTT245 | B96: NIL | C96: 0 | D96: 0 | F96: NIL | G96: 0 | H96: 0 | J96: NIL | K96: 0 | L96: 0 | M96: =SUM(C96,G96,K96) -> 0 | N96: =D96+H96+L96 -> 0
A97: TTT247 | B97: NIL | C97: 0 | D97: 0 | F97: NIL | G97: 0 | H97: 0 | J97: NIL | K97: 0 | L97: 0 | M97: =SUM(C97,H97,K97) -> 0 | N97: =D97+H97+L97 -> 0
A98: TTT248 | B98: PARKING BRAKES -OUT | C98: 0.33333333 | D98: 0 | F98: OUT | G98: 0.33333333 | H98: 0 | J98: OUT | K98: 0.33333333 | L98: 0 | M98: =SUM(C98,G98,K98) -> 1 | N98: =D98+H98+L98 -> 0
...

Sheet BERTH OCCUPANCY
B1: CONTAINER TERMINAL BERTH OCCUPANCY LAST 8HOURS | E1: LAST | F1: 24HRS
B2: ='OTHER REPORTS'!A3 -> TUESDAY 21ST OCTOBER 2025
C3: CRANES IN USE
B4: VESSEL(SHIP NAME) | C4: SHIFT 1 | G4: SHIFT 2 | K4: SHIFT 3
A5: B16 | B5: CANANDRA | C5: 1603 | D5: 1604 | G5: 1603 | H5: 1604 | K5: 1603 | L5: 1604 | M5: 1605
A6: B17A | B6: SATTHA BHUM | C6: 1605 | D6: 1804 | E6: 1901 | G6: 1605 | K6: 1606 | L6: 1804
A7: B17B | B7: NIL
A8: B18 | B8: MSC DAISY | C8: 1902 | D8: 1903 | G8: 1902 | H8: 1903 | L8: 1904 | M8: 1905
A9: B20 | B9: AMU JAMEEL | C9: MHC201 | G9: MHC201 | K9: MHC201 | L9: MHC204
A10: B21A | B10: CMA/CGM FUZHOU | C10: 2101 | K10: 2102 | L10: 2103
A11: B21B | B11: NIL
A12: B22 | B12: MARATHOPOLIS | C12: 2102/2103 | D12: 2201 | E12: 2202 | F12: 2203 | G12: 2201 | H12: 2202 | I12: 2203 | K12: 2201 | L12: 2202 | M12: 2203

Sheet OTHER REPORTS
A1: KENYA PORTS AUTHORITY
A2: CONTAINER TERMINAL ENGINEERING OTHER DATA
A3: TUESDAY 21ST OCTOBER 2025 | B3: EQUIPMENT AVAILABILITY AS AT 0700HRS
A4: EQUIPMENT | B4: AVAILED | D4: REMARKS/FAULTY
A5: SPD-STS | B5: 29 | D5: SPD190 & SPD188
A6: SPD-RMG | B6: 7 | D6: SPD219;SPD 249
A7: SPD-RTG | B7: 50 | D7: SPD101, SPD16 & SPD205
A8: SPD-MHC | B8: 5 | D8: NIL
A9: MANUAL SPREADERS | B9: 22 | D9: NIL
A10: OVER HEIGHT SPREADERS | B10: 13 | D10: OHS180
A11: REEFER POINTS -CT1 | B11: 119 | D11: CT1:[48 POINTS FAULTY AWAITING PO, 120 POINTS BARRICADED AWAITING BACK-UP GENSET] CT2: [24 POINTS FAULTY AWAITING PO]
A12: REEFER POINTS -CT2 | B12: 435
A13: SKELETAL TRAILER | B13: 131 | D13: 27-OUT: BREAKDOWN HTR:169,173,187,195,246,248, 250,277,282, 284, 285, 288,290, 291,292,294,310,330 334,337,369,370,371,372,380,394,397,
A14: LOWBED TRAILER | B14: 10 | D14: NIL
A15: MANLIFT | B15: 1 | D15: ML-01-OUT ML-02-OUT
A16: SHUNTERS | B16: 2 | D16: HPS12 -5TH WHEEL PLATE OUT
A17: FORKLIFTS | B17: 3 | D17: FAULTY:HH123-FAULTY CHARGING SYSTEM
A18: MOBILE CRANES | B18: 1 | D18: NIL
A19: GOOSENECKS | B19: 4 | D19: 5- TAIL SHEARED OUT
A21: UTILITY VEHICLES | B21: 7 | D21: UNDER SERVICE-5, KCD 836G-ACCIDENT. KCD 834G-WRITE-OFF , KCD 839G-GASKET CYLINDER, KCD837G-SUSPENSION;KCA105F-STEERING FAULT;
A22: ACCIDENTS/ INCIDENT | B22: 2 | C22: STS2101. CARTENARY WIRE ROPE PULLEY DETACHED AND FELL DAMAGING A CONTAINER NO.TEMU NO. 0546445 | J22: RTG28 -STEERED INTO CONTAINER
A23: JOBS HANDED OVER TO MAINTENANCE | B23: STS/RMG | C23: STS2101
B24: YARD CRANES | C24: RTG2-05, RTG28
B25: R/STACKERS & ECH
B26: T/TRACTORS & TRAILERS | C26: MRTT118
A27: JOBS HANDED OVER TO MAINTENANCE YET TO BE FINALISED(LONG TERM FAULTS) | B27: GANTRY | C27: RMG05 RTG- 18,19,21,22,23,25, 31,33, 35,39,45, 2-06, 2-07, 2-08, 2-10, 2-20, 2-22 MHC202, MHC203
